Workbook

Sheet Liquiditaet_24M
A1: Liquiditätsplan 24 Monate — Thin Ice Digital UG · KfW StartGeld €120.000 (ohne IBB ProFIT Basisfall) · Berliner Volksbank Vorprüfung
A2: Anforderung Volksbank: monatliche Liquidität ≥ 24 Monate. Umsatz/Wareneinsatz/GF aus Rentabilitätsmodell; Werbung leaner; Zinsen auf €120k tilgungsfrei.
A4: Position | B4: Einheit | C4: M1 | D4: M2 | E4: M3 | F4: M4 | G4: M5 | H4: M6 | I4: M7 | J4: M8 | K4: M9 | L4: M10 | M4: M11 | N4: M12 | O4: M13 | P4: M14 | Q4: M15 | R4: M16 | S4: M17 | T4: M18 | U4: M19 | V4: M20 | W4: M21 | X4: M22 | Y4: M23 | Z4: M24
A5: Periode | C5: Jul-26 | D5: Aug-26 | E5: Sep-26 | F5: Okt-26 | G5: Nov-26 | H5: Dez-26 | I5: Jan-27 | J5: Feb-27 | K5: Mär-27 | L5: Apr-27 | M5: Mai-27 | N5: Jun-27 | O5: Jul-27 | P5: Aug-27 | Q5: Sep-27 | R5: Okt-27 | S5: Nov-27 | T5: Dez-27 | U5: Jan-28 | V5: Feb-28 | W5: Mär-28 | X5: Apr-28 | Y5: Mai-28 | Z5: Jun-28
A7: Anfangsbestand | B7: € | C7: 0 | D7: 112130.23 | E7: 104363.5 | F7: 96794.75 | G7: 89613.87 | H7: 83010.78 | I7: 77175.38 | J7: 77964.22 | K7: 79667.66 | L7: 82285.7 | M7: 85723.4 | N7: 89790.84 | O7: 94203.18 | P7: 100682.15 | Q7: 107786.82 | R7: 115517.21 | S7: 125873.3 | T7: 136708.13 | U7: 148111.71 | V7: 159284.02 | W7: 171025.07 | X7: 183236.88 | Y7: 195979.46 | Z7: 209252.79
A8: Umsatz (Einzahlung) | B8: € | C8: 211 | D8: 527.5 | E8: 949.5 | F8: 1582.5 | G8: 2426.5 | H8: 3481.5 | I8: 4747.5 | J8: 6119 | K8: 7490.5 | L8: 8756.5 | M8: 9811.5 | N8: 10550 | O8: 12849.5 | P8: 13799 | Q8: 14748.5 | R8: 17698 | S8: 18494.2 | T8: 19380.4 | U8: 20266.6 | V8: 21152.8 | W8: 21936.8 | X8: 22780.8 | Y8: 23624.8 | Z8: 24468.8
A9: KfW-Auszahlung | B9: € | C9: 120000 | D9: 0 | E9: 0 | F9: 0 | G9: 0 | H9: 0 | I9: 0 | J9: 0 | K9: 0 | L9: 0 | M9: 0 | N9: 0 | O9: 0 | P9: 0 | Q9: 0 | R9: 0 | S9: 0 | T9: 0 | U9: 0 | V9: 0 | W9: 0 | X9: 0 | Y9: 0 | Z9: 0
A10: Summe Einzahlungen | B10: € | C10: 120211 | D10: 527.5 | E10: 949.5 | F10: 1582.5 | G10: 2426.5 | H10: 3481.5 | I10: 4747.5 | J10: 6119 | K10: 7490.5 | L10: 8756.5 | M10: 9811.5 | N10: 10550 | O10: 12849.5 | P10: 13799 | Q10: 14748.5 | R10: 17698 | S10: 18494.2 | T10: 19380.4 | U10: 20266.6 | V10: 21152.8 | W10: 21936.8 | X10: 22780.8 | Y10: 23624.8 | Z10: 24468.8
A12: Wareneinsatz / Hosting | B12: € | C12: 171.1 | D12: 202.75 | E12: 244.95 | F12: 308.25 | G12: 392.65 | H12: 498.15 | I12: 624.75 | J12: 761.9 | K12: 899.05 | L12: 1025.65 | M12: 1131.15 | N12: 1205 | O12: 1299.95 | P12: 1394.9 | Q12: 1489.85 | R12: 1584.8 | S12: 1673.42 | T12: 1762.04 | U12: 1850.66 | V12: 1939.28 | W12: 2023.68 | X12: 2108.08 | Y12: 2192.48 | Z12: 2276.88
A13: GF-Gehalt | B13: € | C13: 0 | D13: 0 | E13: 0 | F13: 0 | G13: 0 | H13: 0 | I13: 1000 | J13: 1137.93 | K13: 1275.86 | L13: 1413.79 | M13: 1551.72 | N13: 1689.66 | O13: 1827.59 | P13: 1965.52 | Q13: 2103.45 | R13: 2241.38 | S13: 2379.31 | T13: 2517.24 | U13: 3455.17 | V13: 3593.1 | W13: 3731.03 | X13: 3868.97 | Y13: 4006.9 | Z13: 4144.83
A14: Miete / Homeoffice | B14: € | C14: 150 | D14: 150 | E14: 150 | F14: 150 | G14: 150 | H14: 150 | I14: 150 | J14: 150 | K14: 150 | L14: 150 | M14: 150 | N14: 150 | O14: 150 | P14: 150 | Q14: 150 | R14: 150 | S14: 150 | T14: 150 | U14: 150 | V14: 150 | W14: 150 | X14: 150 | Y14: 150 | Z14: 150
A15: Werbung | B15: € | C15: 500 | D15: 681.82 | E15: 863.64 | F15: 1045.45 | G15: 1227.27 | H15: 1409.09 | I15: 1590.91 | J15: 1772.73 | K15: 1954.55 | L15: 2136.36 | M15: 2318.18 | N15: 2500 | O15: 2500 | P15: 2590.91 | Q15: 2681.82 | R15: 2772.73 | S15: 2863.64 | T15: 2954.55 | U15: 3045.45 | V15: 3136.36 | W15: 3227.27 | X15: 3318.18 | Y15: 3409.09 | Z15: 3500
A16: Buchführung | B16: € | C16: 200 | D16: 200 | E16: 200 | F16: 200 | G16: 200 | H16: 200 | I16: 200 | J16: 200 | K16: 200 | L16: 200 | M16: 200 | N16: 200 | O16: 200 | P16: 200 | Q16: 200 | R16: 200 | S16: 200 | T16: 200 | U16: 200 | V16: 200 | W16: 200 | X16: 200 | Y16: 200 | Z16: 200
A17: Zinsen KfW | B17: € | C17: 393 | D17: 393 | E17: 393 | F17: 393 | G17: 393 | H17: 393 | I17: 393 | J17: 393 | K17: 393 | L17: 393 | M17: 393 | N17: 393 | O17: 393 | P17: 393 | Q17: 393 | R17: 393 | S17: 393 | T17: 393 | U17: 393 | V17: 393 | W17: 393 | X17: 393 | Y17: 393 | Z17: 393
A18: Investition | B18: € | C18: 6666.67 | D18: 6666.67 | E18: 6666.67 | F18: 6666.67 | G18: 6666.67 | H18: 6666.67 | I18: 0 | J18: 0 | K18: 0 | L18: 0 | M18: 0 | N18: 0 | O18: 0 | P18: 0 | Q18: 0 | R18: 0 | S18: 0 | T18: 0 | U18: 0 | V18: 0 | W18: 0 | X18: 0 | Y18: 0 | Z18: 0
A19: Summe Auszahlungen | B19: € | C19: 8080.77 | D19: 8294.23 | E19: 8518.25 | F19: 8763.37 | G19: 9029.59 | H19: 9316.91 | I19: 3958.66 | J19: 4415.56 | K19: 4872.46 | L19: 5318.81 | M19: 5744.06 | N19: 6137.66 | O19: 6370.54 | P19: 6694.33 | Q19: 7018.12 | R19: 7341.91 | S19: 7659.37 | T19: 7976.83 | U19: 9094.29 | V19: 9411.75 | W19: 9724.99 | X19: 10038.23 | Y19: 10351.47 | Z19: 10664.71
... A24: Kreditsaldo (€120k) | B24: € | C24: 120000 | D24: 120000 | E24: 120000 | F24: 120000 | G24: 120000 | H24: 120000 | I24: 120000 | J24: 120000 | K24: 120000 | L24: 120000 | M24: 120000 | N24: 120000 | O24: 120000 | P24: 120000 | Q24: 120000 | R24: 120000 | S24: 120000 | T24: 120000 | U24: 120000 | V24: 120000 | W24: 120000 | X24: 120000 | Y24: 120000 | Z24: 120000
A27: Jahresübersicht
A28: Kennzahl | B28: Jahr 1 (M1–12) | C28: Jahr 2 (M13–24)
A29: Umsatz Summe | B29: 56653.5 | C29: 231200.2
A30: Tiefster Kontostand | B30: 77175.38 | C30: 100682.15
A31: Kontostand Jahresende | B31: 94203.18 | C31: 223056.88
A32: Negativer Monat? | B32: Nein | C32: Nein

Sheet Annahmen
A1: ANNAHMEN — Bottom-up-Treiber für Kapitalbedarfsplan & Liquiditätsplan
A2: Identisch zur Rentabilitätsvorschau (Jahr 1) + zusätzliche Annahmen für den Liquiditätsplan (Abschnitt 10).
A4: 1. RUNNR SAAS — PREISE & ABO-MIX
A5: Basic-Tarif (€/Monat) | B5: 19
A6: Pro-Tarif (€/Monat) | B6: 25
A7: Anteil Pro-Tarif an Neuabos | B7: 0.35
A8: → Blended ARPU (€/Monat) | B8: =B5*(1-B7)+B6*B7
A10: 2. BROKER-PARTNERSCHAFT — Flat-Fee pro Vermittlung (ab "Month 13")
A11: CPA-Gebühr pro Vermittlung (€) | B11: 150 | C11: Platzhalter — irrelevant für Jahr 1 (Start erst Monat 13)
A12: Konversionsrate Neuabo → Broker-Signup | B12: 0.2
A13: Startmonat (1–36) | B13: 13
A15: 3. WARENEINSATZ (Hosting, Infrastruktur, Plattformgebühren)
A16: Whop-Plattformgebühr (% vom Runnr-Umsatz) | B16: 0.1
A17: Fixe Infrastrukturkosten (€/Monat) | B17: 150
A19: 4. PERSONALKOSTEN — Geschäftsführergehalt als linearer Ramp
A20: Geschäftsführergehalt ab Monat 7 (Start, €/Monat) | B20: 1000 | C20: Nach ALG-I-Ende (Annahmen!B61). €0 in Monat 1-6, da Haushalt via ALG I+Kindergeld+Auslandseinkommen selbsttragend (Überschuss €1.715/Monat, siehe Selbstauskunft)
A21: Geschäftsführergehalt Monat 36 (€/Monat) | B21: 5000 | C21: Zielwert Ende Jahr 3, unverändert — für Jahr 1 nur die Interpolation relevant
A22: Freelancer-Honorar Jahr 2 (€/Monat) | B22: 800 | C22: irrelevant für Jahr 1
A23: Freelancer-Honorar Jahr 3 (€/Monat) | B23: 1000
A24: Freelancer Startmonat (1–36) | B24: 500
B25: 2500
A26: 5. SONSTIGE BETRIEBSKOSTEN — Werbung als linearer Ramp
A27: Miete / Homeoffice-Pauschale (€/Monat) | B27: 150
A28: Werbung Monat 1 (€/Monat) | B28: 600 | C28: entspricht der Ausgangsbasis für die Marketing-Zeile im Liquiditätsplan
A29: Werbung Monat 36 (€/Monat) | B29: 3000
A30: Buchführung / Steuerberater (€/Monat) | B30: 200
A32: 6. INVESTITION & ABSCHREIBUNG (AfA)
A33: Investitionsvolumen (€) | B33: 40000 | C33: entspricht dem Investitionsanteil aus dem KfW-Antrag (Software/IP, Infrastruktur, Equipment)
A34: Nutzungsdauer (Jahre) | B34: 3
A35: → Jährliche AfA (€) | B35: =B33/B34
A36: → Monatliche AfA (€) | B36: =B35/12
A38: 7. KFW-STARTGELD-DARLEHEN (067) | B38: 120000
A39: Auszahlungsbetrag (€) | B39: 120000
A40: Restsaldo nach ProFIT-Sondertilgung (€) | B40: 0
A41: Monat der ProFIT-Sondertilgung (1–36) | B41: 6 | C41: Dezember 2026 = Monat 6
A42: Effektiver Jahreszins | B42: 0.0393
A43: → Monatlicher Zinssatz | B43: =B42/12
A44: Tilgungsfreie Anlaufjahre | B44: 2
A45: Gesamtlaufzeit (Jahre) | B45: 10
A46: → Tilgungsmonate | B46: =(B45-B44)*12
...

Sheet Kapitalbedarfsplan
A1: KAPITALBEDARFSPLAN — KfW-StartGeld (067)
A2: Einmaliger Kapitalbedarf zur Gründung / Anlaufphase von Thin Ice Digital UG (Runnr & Glacifraga)
A4: 1. INVESTITIONSBEDARF
A5: Software/IP-Entwicklung, Infrastruktur, Equipment (gesamt) | B5: 89000 | C5: Entspricht Annahmen!B33. Detailaufstellung gemäß ursprünglicher KfW-Antragsunterlage (Einzelpositionen dort verfügbar).
A7: 2. BETRIEBSMITTEL
A8: Working Capital Anlaufphase (Jahr 1, siehe Liquiditätsplan) | B8: 40000 | C8: Deckt den operativen Liquiditätsbedarf bis zur Profitabilität in Jahr 2 (Geschäftsführergehalt, Werbung, Wareneinsatz, Zinsen etc.)
A10: 3. RESERVE
A11: Working Capital Anlaufphase — Runnr-Launch, Marketing, GF-Gehalt ab Monat 7; ohne IBB-ProFIT-Abhängigkeit. | B11: 79000 | C11: Kleiner Puffer für einmalige Gründungsnebenkosten
A13: GESAMTBEDARF (KfW-StartGeld-Antrag) | B13: =B5+B8+B11
B14: 1000
A15: Hinweis: Die Aufteilung Investition/Betriebsmittel folgt der bereits eingereichten ProFIT-/KfW-Struktur (€89.000 Investitionsanteil + €80.000 Betriebsmittel + €1.000 Reserve = €170.000). Die Plausibilität der Betriebsmittel-Höhe wird im Liquiditätsplan (Sheet 'Liquiditaetsplan') Monat für Monat nachgewiesen.
A17: KfW StartGeld €120.000. Software weitgehend fertig. 24-Monats-Liquidität siehe Blatt Liquiditaet_24M (Volksbank-Anforderung). | B17: 120000

Sheet Liquiditaetsplan
A1: LIQUIDITÄTSPLAN — Jahr 1 (Jul-26 bis Jun-27)
A2: Monatlicher Kontostand unter Annahme: KfW-Auszahlung €170.000 zu Monat 1, ProFIT-Zuwendung €81.200 zu Monat 6 (sofort als Sondertilgung an die Bank weitergeleitet).
A4: Monatlicher Kontostand Jahr 1. Vollständige 24 Monate: Blatt Liquiditaet_24M. | C4: 1 | D4: 2 | E4: 3 | F4: 4 | G4: 5 | H4: 6 | I4: 7 | J4: 8 | K4: 9 | L4: 10 | M4: 11 | N4: 12
A5: Periode | C5: Jul-26 | D5: Aug-26 | E5: Sep-26 | F5: Okt-26 | G5: Nov-26 | H5: Dez-26 | I5: Jan-27 | J5: Feb-27 | K5: Mär-27 | L5: Apr-27 | M5: Mai-27 | N5: Jun-27
A7: Anfangsbestand (€) | C7: 1 | D7: 2 | E7: 3 | F7: 4 | G7: 5 | H7: 6 | I7: 7 | J7: 8 | K7: 9 | L7: 10 | M7: 11 | N7: 12
C8: Jul-26 | D8: Aug-26 | E8: Sep-26 | F8: Okt-26 | G8: Nov-26 | H8: Dez-26 | I8: Jan-27 | J8: Feb-27 | K8: Mär-27 | L8: Apr-27 | M8: Mai-27 | N8: Jun-27
A9: EINZAHLUNGEN | C9: 0 | D9: 112130.23 | E9: 104363.5 | F9: 96794.75 | G9: 89613.87 | H9: 83010.78 | I9: 77175.38 | J9: 77964.22 | K9: 79667.66 | L9: 82285.7 | M9: 85723.4 | N9: 89790.84
A10: Umsatzerlöse (Runnr SaaS) | C10: =Monatsdetail_J1!C13 | D10: =Monatsdetail_J1!D13 | E10: =Monatsdetail_J1!E13 | F10: =Monatsdetail_J1!F13 | G10: =Monatsdetail_J1!G13 | H10: =Monatsdetail_J1!H13 | I10: =Monatsdetail_J1!I13 | J10: =Monatsdetail_J1!J13 | ... N10: =Monatsdetail_J1!N13
A11: KfW-Darlehen-Auszahlung | C11: 211 | D11: 527.5 | E11: 949.5 | F11: 1582.5 | G11: 2426.5 | H11: 3481.5 | I11: 4747.5 | J11: 6119 | K11: 7490.5 | L11: 8756.5 | M11: 9811.5 | N11: 10550
A12: ProFIT-Zuwendung (IBB) | C12: 120000 | D12: 0 | E12: 0 | F12: 0 | G12: 0 | H12: 0 | I12: 0 | J12: 0 | K12: 0 | L12: 0 | M12: 0 | N12: 0
A13: SUMME EINZAHLUNGEN | C13: 0 | D13: 0 | E13: 0 | F13: 0 | G13: 0 | H13: 0 | I13: 0 | J13: 0 | K13: 0 | L13: 0 | M13: 0 | N13: 0
C14: 120211 | D14: 527.5 | E14: 949.5 | F14: 1582.5 | G14: 2426.5 | H14: 3481.5 | I14: 4747.5 | J14: 6119 | K14: 7490.5 | L14: 8756.5 | M14: 9811.5 | N14: 10550
A15: AUSZAHLUNGEN
A16: Wareneinsatz | C16: 171.1 | D16: 202.75 | E16: 244.95 | F16: 308.25 | G16: 392.65 | H16: 498.15 | I16: 624.75 | J16: 761.9 | K16: 899.05 | L16: 1025.65 | M16: 1131.15 | N16: 1205
A17: Personal (Geschäftsführergehalt) | C17: 0 | D17: 0 | E17: 0 | F17: 0 | G17: 0 | H17: 0 | I17: 1000 | J17: 1137.93 | K17: 1275.86 | L17: 1413.79 | M17: 1551.72 | N17: 1689.66
A18: Miete / Homeoffice | C18: 150 | D18: 150 | E18: 150 | F18: 150 | G18: 150 | H18: 150 | I18: 150 | J18: 150 | K18: 150 | L18: 150 | M18: 150 | N18: 150
A19: Werbung | C19: 500 | D19: 681.82 | E19: 863.64 | F19: 1045.45 | G19: 1227.27 | H19: 1409.09 | I19: 1590.91 | J19: 1772.73 | K19: 1954.55 | L19: 2136.36 | M19: 2318.18 | N19: 2500
A20: Buchführung / Steuerberater | C20: 200 | D20: 200 | E20: 200 | F20: 200 | G20: 200 | H20: 200 | I20: 200 | J20: 200 | K20: 200 | L20: 200 | M20: 200 | N20: 200
A21: Zinsen (KfW-Darlehen) | C21: 393 | D21: 393 | E21: 393 | F21: 393 | G21: 393 | H21: 393 | I21: 393 | J21: 393 | K21: 393 | L21: 393 | M21: 393 | N21: 393
A22: Investitionsauszahlung | C22: 6666.67 | D22: 6666.67 | E22: 6666.67 | F22: 6666.67 | G22: 6666.67 | H22: 6666.67 | I22: 0 | J22: 0 | K22: 0 | L22: 0 | M22: 0 | N22: 0
A23: ProFIT-Sondertilgung an Bank | C23: 0 | D23: 0 | E23: 0 | F23: 0 | G23: 0 | H23: 0 | I23: 0 | J23: 0 | K23: 0 | L23: 0 | M23: 0 | N23: 0
A24: Reguläre Tilgung | C24: 0 | D24: 0 | E24: 0 | F24: 0 | G24: 0 | H24: 0 | I24: 0 | J24: 0 | K24: 0 | L24: 0 | M24: 0 | N24: 0
A25: Steuern | C25: 0 | D25: 0 | E25: 0 | F25: 0 | G25: 0 | H25: 0 | I25: 0 | J25: 0 | K25: 0 | L25: 0 | M25: 0 | N25: 0 | O25: Jahr 1 = Verlust → Steuern = 0 (siehe Rentabilitätsvorschau)
A26: SUMME AUSZAHLUNGEN | C26: 8080.77 | D26: 8294.23 | E26: 8518.25 | F26: 8763.37 | G26: 9029.59 | H26: 9316.91 | I26: 3958.66 | J26: 4415.56 | K26: 4872.46 | L26: 5318.81 | M26: 5744.06 | N26: 6137.66
C27: 112130.23 | D27: -7766.73 | E27: -7568.75 | F27: -7180.87 | G27: -6603.09 | H27: -5835.41 | I27: 788.84 | J27: 1703.44 | K27: 2618.04 | L27: 3437.69 | M27: 4067.44 | N27: 4412.34
A28: SALDO DES MONATS | C28: 112130.23 | D28: 104363.5 | E28: 96794.75 | F28: 89613.87 | G28: 83010.78 | H28: 77175.38 | I28: 77964.22 | J28: 79667.66 | K28: 82285.7 | L28: 85723.4 | M28: 89790.84 | N28: 94203.18
A29: ENDBESTAND | C29: =C7+C28 | D29: =D7+D28 | E29: =E7+E28 | F29: =F7+F28 | G29: =G7+G28 | H29: =H7+H28 | I29: =I7+I28 | J29: =J7+J28 | ... N29: =N7+N28

Sheet Monatsdetail_J1
A1: MONATSDETAIL JAHR 1 — Jul-26 bis Jun-27 (identisch zu Rentabilitätsvorschau, nur Monate 1-12)
A2: Grüne Zeilen = Eingaben (editierbar) | Schwarze Zeilen = Formeln
A4: Monat # | C4: 1 | D4: 2 | E4: 3 | F4: 4 | G4: 5 | H4: 6 | I4: 7 | J4: 8 | K4: 9 | L4: 10 | M4: 11 | N4: 12
A5: Periode | C5: Jul-26 | D5: Aug-26 | E5: Sep-26 | F5: Okt-26 | G5: Nov-26 | H5: Dez-26 | I5: Jan-27 | J5: Feb-27 | K5: Mär-27 | L5: Apr-27 | M5: Mai-27 | N5: Jun-27
A7: Netto-Neuzugänge zahlende Abos (Stk.) | C7: 10 | D7: 15 | E7: 20 | F7: 30 | G7: 40 | H7: 50 | I7: 60 | J7: 65 | K7: 65 | L7: 60 | M7: 50 | N7: 35
A8: Kumulierte zahlende Abos (Stk.) | C8: =C7 | D8: =C8+D7 | E8: =D8+E7 | F8: =E8+F7 | G8: =F8+G7 | H8: =G8+H7 | I8: =H8+I7 | J8: =I8+J7 | K8: =J8+K7 | ... N8: =M8+N7
A9: Runnr SaaS-Umsatz (€) | C9: =C8*Annahmen!$B$8 | D9: =D8*Annahmen!$B$8 | E9: =E8*Annahmen!$B$8 | F9: =F8*Annahmen!$B$8 | G9: =G8*Annahmen!$B$8 | H9: =H8*Annahmen!$B$8 | I9: =I8*Annahmen!$B$8 | J9: =J8*Annahmen!$B$8 | ... N9: =N8*Annahmen!$B$8
A10: Broker-Vermittlungen (Stk.) | C10: =IF(C4>=Annahmen!$B$13,C7*Annahmen!$B$12,0) | D10: =IF(D4>=Annahmen!$B$13,D7*Annahmen!$B$12,0) | E10: =IF(E4>=Annahmen!$B$13,E7*Annahmen!$B$12,0) | F10: =IF(F4>=Annahmen!$B$13,F7*Annahmen!$B$12,0) | G10: =IF(G4>=Annahmen!$B$13,G7*Annahmen!$B$12,0) | H10: =IF(H4>=Annahmen!$B$13,H7*Annahmen!$B$12,0) | I10: =IF(I4>=Annahmen!$B$13,I7*Annahmen!$B$12,0) | J10: =IF(J4>=Annahmen!$B$13,J7*Annahmen!$B$12,0) | ... N10: =IF(N4>=Annahmen!$B$13,N7*Annahmen!$B$12,0)
A11: Broker-Umsatz (€) | C11: =C10*Annahmen!$B$11 | D11: =D10*Annahmen!$B$11 | E11: =E10*Annahmen!$B$11 | F11: =F10*Annahmen!$B$11 | G11: =G10*Annahmen!$B$11 | H11: =H10*Annahmen!$B$11 | I11: =I10*Annahmen!$B$11 | J11: =J10*Annahmen!$B$11 | ... N11: =N10*Annahmen!$B$11
A12: Glacifraga-Umsatz (€) | C12: 0 | D12: 0 | E12: 0 | F12: 0 | G12: 0 | H12: 0 | I12: 0 | J12: 0 | K12: 0 | L12: 0 | M12: 0 | N12: 0
A13: GESAMTUMSATZ (€) | C13: =C9+C11+C12 | D13: =D9+D11+D12 | E13: =E9+E11+E12 | F13: =F9+F11+F12 | G13: =G9+G11+G12 | H13: =H9+H11+H12 | I13: =I9+I11+I12 | J13: =J9+J11+J12 | ... N13: =N9+N11+N12
A14: Wareneinsatz (€) | C14: =C9*Annahmen!$B$16+Annahmen!$B$17 | D14: =D9*Annahmen!$B$16+Annahmen!$B$17 | E14: =E9*Annahmen!$B$16+Annahmen!$B$17 | F14: =F9*Annahmen!$B$16+Annahmen!$B$17 | G14: =G9*Annahmen!$B$16+Annahmen!$B$17 | H14: =H9*Annahmen!$B$16+Annahmen!$B$17 | I14: =I9*Annahmen!$B$16+Annahmen!$B$17 | J14: =J9*Annahmen!$B$16+Annahmen!$B$17 | ... N14: =N9*Annahmen!$B$16+Annahmen!$B$17
A15: Rohertrag (€) | C15: =C13-C14 | D15: =D13-D14 | E15: =E13-E14 | F15: =F13-F14 | G15: =G13-G14 | H15: =H13-H14 | I15: =I13-I14 | J15: =J13-J14 | ... N15: =N13-N14
A16: Personal (€) | C16: =IF(C4<=Annahmen!$B$61,0,Annahmen!$B$20+(Annahmen!$B$21-Annahmen!$B$20)*(C4-Annahmen!$B$61-1)/(35-Annahmen!$B$61))+IF(C4<Annahmen!$B$24,0,IF(C4<=24,Annahmen!$B$22,Annahmen!$B$23)) | D16: =IF(D4<=Annahmen!$B$61,0,Annahmen!$B$20+(Annahmen!$B$21-Annahmen!$B$20)*(D4-Annahmen!$B$61-1)/(35-Annahmen!$B$61))+IF(D4<Annahmen!$B$24,0,IF(D4<=24,Annahmen!$B$22,Annahmen!$B$23)) | E16: =IF(E4<=Annahmen!$B$61,0,Annahmen!$B$20+(Annahmen!$B$21-Annahmen!$B$20)*(E4-Annahmen!$B$61-1)/(35-Annahmen!$B$61))+IF(E4<Annahmen!$B$24,0,IF(E4<=24,Annahmen!$B$22,Annahmen!$B$23)) | F16: =IF(F4<=Annahmen!$B$61,0,Annahmen!$B$20+(Annahmen!$B$21-Annahmen!$B$20)*(F4-Annahmen!$B$61-1)/(35-Annahmen!$B$61))+IF(F4<Annahmen!$B$24,0,IF(F4<=24,Annahmen!$B$22,Annahmen!$B$23)) | G16: =IF(G4<=Annahmen!$B$61,0,Annahmen!$B$20+(Annahmen!$B$21-Annahmen!$B$20)*(G4-Annahmen!$B$61-1)/(35-Annahmen!$B$61))+IF(G4<Annahmen!$B$24,0,IF(G4<=24,Annahmen!$B$22,Annahmen!$B$23)) | H16: =IF(H4<=Annahmen!$B$61,0,Annahmen!$B$20+(Annahmen!$B$21-Annahmen!$B$20)*(H4-Annahmen!$B$61-1)/(35-Annahmen!$B$61))+IF(H4<Annahmen!$B$24,0,IF(H4<=24,Annahmen!$B$22,Annahmen!$B$23)) | I16: =IF(I4<=Annahmen!$B$61,0,Annahmen!$B$20+(Annahmen!$B$21-Annahmen!$B$20)*(I4-Annahmen!$B$61-1)/(35-Annahmen!$B$61))+IF(I4<Annahmen!$B$24,0,IF(I4<=24,Annahmen!$B$22,Annahmen!$B$23)) | J16: =IF(J4<=Annahmen!$B$61,0,Annahmen!$B$20+(Annahmen!$B$21-Annahmen!$B$20)*(J4-Annahmen!$B$61-1)/(35-Annahmen!$B$61))+IF(J4<Annahmen!$B$24,0,IF(J4<=24,Annahmen!$B$22,Annahmen!$B$23)) | ... N16: =IF(N4<=Annahmen!$B$61,0,Annahmen!$B$20+(Annahmen!$B$21-Annahmen!$B$20)*(N4-Annahmen!$B$61-1)/(35-Annahmen!$B$61))+IF(N4<Annahmen!$B$24,0,IF(N4<=24,Annahmen!$B$22,Annahmen!$B$23))
A17: Miete/Homeoffice (€) | C17: =Annahmen!$B$27 | D17: =Annahmen!$B$27 | E17: =Annahmen!$B$27 | F17: =Annahmen!$B$27 | G17: =Annahmen!$B$27 | H17: =Annahmen!$B$27 | I17: =Annahmen!$B$27 | J17: =Annahmen!$B$27 | ... N17: =Annahmen!$B$27
A18: Werbung (€) | C18: =Annahmen!$B$28+(Annahmen!$B$29-Annahmen!$B$28)*(C4-1)/35 | D18: =Annahmen!$B$28+(Annahmen!$B$29-Annahmen!$B$28)*(D4-1)/35 | E18: =Annahmen!$B$28+(Annahmen!$B$29-Annahmen!$B$28)*(E4-1)/35 | F18: =Annahmen!$B$28+(Annahmen!$B$29-Annahmen!$B$28)*(F4-1)/35 | G18: =Annahmen!$B$28+(Annahmen!$B$29-Annahmen!$B$28)*(G4-1)/35 | H18: =Annahmen!$B$28+(Annahmen!$B$29-Annahmen!$B$28)*(H4-1)/35 | I18: =Annahmen!$B$28+(Annahmen!$B$29-Annahmen!$B$28)*(I4-1)/35 | J18: =Annahmen!$B$28+(Annahmen!$B$29-Annahmen!$B$28)*(J4-1)/35 | ... N18: =Annahmen!$B$28+(Annahmen!$B$29-Annahmen!$B$28)*(N4-1)/35
A19: Buchführung (€) | C19: =Annahmen!$B$30 | D19: =Annahmen!$B$30 | E19: =Annahmen!$B$30 | F19: =Annahmen!$B$30 | G19: =Annahmen!$B$30 | H19: =Annahmen!$B$30 | I19: =Annahmen!$B$30 | J19: =Annahmen!$B$30 | ... N19: =Annahmen!$B$30
A20: Abschreibung (€) | C20: =Annahmen!$B$36 | D20: =Annahmen!$B$36 | E20: =Annahmen!$B$36 | F20: =Annahmen!$B$36 | G20: =Annahmen!$B$36 | H20: =Annahmen!$B$36 | I20: =Annahmen!$B$36 | J20: =Annahmen!$B$36 | ... N20: =Annahmen!$B$36
A21: BETRIEBSERGEBNIS / EBIT (€) | C21: =C15-C16-C17-C18-C19-C20 | D21: =D15-D16-D17-D18-D19-D20 | E21: =E15-E16-E17-E18-E19-E20 | F21: =F15-F16-F17-F18-F19-F20 | G21: =G15-G16-G17-G18-G19-G20 | H21: =H15-H16-H17-H18-H19-H20 | I21: =I15-I16-I17-I18-I19-I20 | J21: =J15-J16-J17-J18-J19-J20 | ... N21: =N15-N16-N17-N18-N19-N20
A23: Kreditsaldo Beginn (€) | C23: =Annahmen!$B$39 | D23: =C27 | E23: =D27 | F23: =E27 | G23: =F27 | H23: =G27 | I23: =H27 | J23: =I27 | K23: =J27 | ... N23: =M27
A24: ProFIT-Sondertilgung (€) | C24: =IF(C4=Annahmen!$B$41,Annahmen!$B$39-Annahmen!$B$40,0) | D24: =IF(D4=Annahmen!$B$41,Annahmen!$B$39-Annahmen!$B$40,0) | E24: =IF(E4=Annahmen!$B$41,Annahmen!$B$39-Annahmen!$B$40,0) | F24: =IF(F4=Annahmen!$B$41,Annahmen!$B$39-Annahmen!$B$40,0) | G24: =IF(G4=Annahmen!$B$41,Annahmen!$B$39-Annahmen!$B$40,0) | H24: =IF(H4=Annahmen!$B$41,Annahmen!$B$39-Annahmen!$B$40,0) | I24: =IF(I4=Annahmen!$B$41,Annahmen!$B$39-Annahmen!$B$40,0) | J24: =IF(J4=Annahmen!$B$41,Annahmen!$B$39-Annahmen!$B$40,0) | ... N24: =IF(N4=Annahmen!$B$41,Annahmen!$B$39-Annahmen!$B$40,0)
A25: Zinsen (€) | C25: =(C23-C24)*Annahmen!$B$43 | D25: =(D23-D24)*Annahmen!$B$43 | E25: =(E23-E24)*Annahmen!$B$43 | F25: =(F23-F24)*Annahmen!$B$43 | G25: =(G23-G24)*Annahmen!$B$43 | H25: =(H23-H24)*Annahmen!$B$43 | I25: =(I23-I24)*Annahmen!$B$43 | J25: =(J23-J24)*Annahmen!$B$43 | ... N25: =(N23-N24)*Annahmen!$B$43
A26: Reguläre Tilgung (€) | C26: =IF(C4>Annahmen!$B$44*12,Annahmen!$B$47,0) | D26: =IF(D4>Annahmen!$B$44*12,Annahmen!$B$47,0) | E26: =IF(E4>Annahmen!$B$44*12,Annahmen!$B$47,0) | F26: =IF(F4>Annahmen!$B$44*12,Annahmen!$B$47,0) | G26: =IF(G4>Annahmen!$B$44*12,Annahmen!$B$47,0) | H26: =IF(H4>Annahmen!$B$44*12,Annahmen!$B$47,0) | I26: =IF(I4>Annahmen!$B$44*12,Annahmen!$B$47,0) | J26: =IF(J4>Annahmen!$B$44*12,Annahmen!$B$47,0) | ... N26: =IF(N4>Annahmen!$B$44*12,Annahmen!$B$47,0)
A27: Kreditsaldo Ende (€) | C27: =C23-C24-C26 | D27: =D23-D24-D26 | E27: =E23-E24-E26 | F27: =F23-F24-F26 | G27: =G23-G24-G26 | H27: =H23-H24-H26 | I27: =I23-I24-I26 | J27: =J23-J24-J26 | ... N27: =N23-N24-N26
A29: EBT vor Steuern (€) | C29: =C21-C25 | D29: =D21-D25 | E29: =E21-E25 | F29: =F21-F25 | G29: =G21-G25 | H29: =H21-H25 | I29: =I21-I25 | J29: =J21-J25 | ... N29: =N21-N25
