Workbook

Sheet Herleitung
A1: HERLEITUNG DER RENTABILITÄTSVORSCHAU — Methodik & Annahmen
A2: Thin Ice Digital UG (haftungsbeschränkt) — Produkte: Runnr (B2C SaaS) und Glacifraga (B2B Institutional) | Geschäftsjahre 1–3: Juli 2026 – Juni 2029
A4: 1. Zweck und Aufbau
A5: Diese Rentabilitätsvorschau wurde bottom-up aus monatlichen Treibern abgeleitet (Sheet "Monatsdetail", 36 Monate) und auf dem Sheet "Rentabilitaet" zu drei Geschäftsjahren zusammengefasst. Alle Eingabeparameter liegen zentral im Sheet "Annahmen": blaue Zellen sind editierbare Eingaben, gelb hinterlegte Zellen sind Platzhalter, die vor Einreichung final bestätigt werden sollten (siehe Abschnitt 10). Thin Ice Digital UG betreibt zwei Produkte unter einem Dach — Runnr als Hauptumsatzträger und Glacifraga als bewusst konservativ angesetzte Zweitsäule.
A7: 2. Runnr SaaS — Umsatzherleitung
A8: Preismodell: zwei Tarife, Basic €19/Monat und Pro €25/Monat, mit einem angenommenen Pro-Anteil von 35% der Neuabos (Annahmen!B5:B7). Daraus ergibt sich ein gewichteter ARPU (Average Revenue Per User) von €21,10/Monat (Annahmen!B8).
A9: Abo-Wachstum: Die monatlichen Netto-Neuzugänge (Monatsdetail Zeile 8) folgen einer S-Kurve — langsamer Start in der Soft-Launch-Phase, Beschleunigung zur Jahresmitte, leichte Abflachung gegen Jahresende. Daraus ergeben sich kumuliert 500 zahlende Abos am Ende von Jahr 1, ca. 1.008 am Ende von Jahr 2 (≈2,0x) und ca. 1.922 am Ende von Jahr 3 (≈1,9x) — eine ungefähre Verdopplung pro Jahr, ein etabliertes und für ein Produkt mit organischem Funnel über Whop.com sowie bestehender Social-Media-Reichweite konservativ einstufbares SaaS-Wachstumsmuster. Der monatliche Runnr-Umsatz ergibt sich jeweils aus kumulierten zahlenden Abos × ARPU.
A10: Hinweis zur Umsatzentwicklung zwischen den Jahren: Der nominale Sprung von Jahr 1 auf Jahr 2 ist ein Basiseffekt der S-Kurve — Jahr 1 endet mit einer Monats-Run-Rate von ca. €11.700 (×12 = €140.400 p.a.), während der Jahresdurchschnitt durch die Anlaufphase niedriger liegt. Die Exit-Run-Rate (letzter Monat × 12, siehe Sheet "Rentabilitaet") verläuft dagegen glatt von €140.400 (Jahr 1) über €321.446 (Jahr 2) auf €623.218 (Jahr 3) — ein Faktor von rund 2,2x pro Jahr, der die tatsächliche Wachstumsdynamik deutlich realistischer abbildet als der nominale Jahresvergleich.
A12: 3. Broker-Partnerschaft — CPA-Modell ("Month-13-Trigger")
A13: Ab Monat 13 (= Beginn Jahr 2) wird eine zweite Umsatzquelle aktiv: eine Flat-Fee (CPA, "Cost per Acquisition") pro Trader, der sich über Runnr beim Partnerbroker registriert. Angenommen werden €150 pro Vermittlung (Annahmen!B11, Platzhalter — marktüblich €100–300, final mit dem Partnerbroker zu verhandeln) und eine Konversionsquote von 20% der monatlichen Netto-Neuabos (Annahmen!B12). Dieser Zeitpunkt entspricht dem geplanten Break-even zu Beginn von Jahr 2.
A15: 4. Glacifraga Institutional — konservative Zweitsäule
A16: Glacifraga ist ein bereits entwickeltes, live laufendes algorithmisches Signal-System (Backtests der konservativen Konfiguration "Baron von Richstone": Profit-Faktor 3,45, Sharpe 7,96, Max Drawdown -2,5%). Die institutionelle Vermarktung läuft bereits über mehrere Kontaktaufnahmen zu Prop-Trading-Firmen und Bank-Quant-Desks.
... A35: 9. Zusammenfassung — Kapitaldienstfähigkeit (inkl. Sensitivität "ohne Glacifraga")
B37: Jahr 1 | C37: Jahr 2 | D37: Jahr 3
A38: EBT vor Steuern | B38: -9293 | C38: 114813 | D38: 281311
A39: Jahresüberschuss | B39: -9293 | C39: 83157 | D39: 196918
A40: Verfügbares Einkommen (mit Glacifraga) | B40: 20374 | C40: 112824 | D40: 215484
A41: Verfügbares Einkommen (ohne Glacifraga) | B41: 20374 | C41: 100224 | D41: 181884
A42: Differenz durch Glacifraga (nach Steuern) | B42: 0 | C42: 12600 | D42: 33600
A44: Fazit: Bereits ohne Glacifraga-Beitrag ist das Modell in allen drei Jahren cashflow-positiv — inklusive Jahr 1 (€20.374), das dank der ALG-I-gestützten Personalkosten-Phasierung von Beginn an einen Überschuss erzielt, statt wie in einer früheren Modellversion einen Fehlbetrag. Jahr 2/3 zeigen deutlich positive, wachsende Cashflows (€100.224 bzw. €181.884), die die ab Jahr 3 beginnende Tilgung (€11.100/Jahr) um ein Vielfaches übersteigen. Glacifraga liefert einen zusätzlichen Cashflow-Puffer von €12.600 (Jahr 2) bzw. €33.600 (Jahr 3) nach Steuern — ein willkommenes Plus, aber kein Bestandteil der Kapitaldienstfähigkeits-Argumentation.
A46: 10. Offene Punkte vor Einreichung (gelb markiert in "Annahmen")
A47: • Broker-CPA €150/Vermittlung (Annahmen!B11): Platzhalter — mit tatsächlichem Partnerbroker final verhandeln.
A48: • AfA-Nutzungsdauer 3 Jahre (Annahmen!B34): final mit dem Steuerberater abstimmen.
A49: • KfW-Laufzeit/tilgungsfreie Jahre, 10/2 (Annahmen!B44–B45): final mit der Deutsche Bank klären.
A50: • Effektiver Unternehmenssteuersatz 30% (Annahmen!B50): final mit dem Steuerberater abstimmen.
A51: • Werbung-Zielwert €3.000/Monat in Monat 36 (Annahmen!B29): Influencer-Budget noch unsicher, ggf. nach unten anpassen.
A52: • GF-Gehalt-Ramp (Annahmen!B20–B21, B58): jetzt direkt aus der Selbstauskunft abgeleitet — ALG I läuft bis Dez-26 (Monat 6), danach Deckungslücke €785/Monat im Haushalt. Der Startwert €1.000/Monat ab Monat 7 enthält einen Puffer von €215 über diesem Minimum und kann bei Bedarf angepasst werden. Werbung-Startwert €600/Monat in Monat 1 (Annahmen!B28) bleibt ein Platzhalter und sollte mit dem 12-Monats-Budget (Kapitalbedarfsplan/Liquiditätsplan, mit denselben Annahmen aufgebaut) final abgestimmt werden.
A54: 11. UPSIDE-SZENARIO: WHITE-LABEL-LIZENZIERUNG (zusätzlich, nicht im Basismodell enthalten)
A55: Eine frühere IBB-Ventures-Pitch enthielt zusätzlich ein White-Label-Lizenzmodell für Retail-Broker (Setup-Gebühr + monatliche Lizenz, zwei aktive Deals bis Jahr 3). Dies ist strukturell verschieden vom CPA-Vermittlungsmodell (Annahmen!B11–B13): Beim White-Label betreibt der Broker Runnr unter eigener Marke — eine deutlich tiefere Integration mit längerem Sales-Zyklus und höherem Betreuungsaufwand als eine einfache Affiliate-Vermittlung.
A56: Da hierzu aktuell kein konkreter Interessent vorliegt, ist dieser Umsatz bewusst NICHT in Monatsdetail/Rentabilitaet eingerechnet — die Kernaussage bleibt auf bereits verifizierten Annahmen (Selbstauskunft, Subscriber-Ramp, Glacifraga-Pilot) aufgebaut. Zur Orientierung, falls sich ein Deal konkretisiert:
B58: Wert
A59: Setup-Gebühr pro Deal (einmalig) | B59: =Annahmen!B61
A60: Laufende Lizenzgebühr pro Deal (Jahres-Run-Rate) | B60: =Annahmen!B62*12
A61: Bei 2 aktiven Deals: Jahres-Run-Rate Umsatz | B61: =Annahmen!B62*12*2
A62: davon nach Steuern (vereinfacht, ohne separate Wareneinsatz) | B62: =Annahmen!B62*12*2*(1-Annahmen!B50)
A64: Bei zwei Deals entspräche das einer zusätzlichen Run-Rate von rund €72.000/Jahr Umsatz bzw. ~€50.400/Jahr nach Steuern (vereinfacht, ohne separate Integrations-/Supportkosten) — zuzüglich der einmaligen Setup-Gebühren (2 × €25.000 = €50.000) im Jahr des jeweiligen Vertragsabschlusses. Sollte sich im Lauf von Jahr 2/3 ein konkreter White-Label-Interessent ergeben, kann dieses Szenario in einer aktualisierten Version analog zu Glacifraga als dritte Umsatzquelle in Monatsdetail/Rentabilitaet eingebaut werden.

Sheet Annahmen
A1: ANNAHMEN — Bottom-up-Treiber für die Rentabilitätsvorschau
A2: Blaue Zellen = editierbare Eingaben. Gelb hinterlegt = Platzhalter, mit deinen echten Zahlen ersetzen.
A4: 1. RUNNR SAAS — PREISE & ABO-MIX
A5: Basic-Tarif (€/Monat) | B5: 19
A6: Pro-Tarif (€/Monat) | B6: 25
A7: Anteil Pro-Tarif an Neuabos | B7: 0.35
A8: → Blended ARPU (€/Monat) | B8: =B5*(1-B7)+B6*B7 | C8: Durchschnittlicher Umsatz pro zahlendem Abo/Monat, gewichtet nach Tarif-Mix
A10: 2. BROKER-PARTNERSCHAFT — Flat-Fee pro Vermittlung (ab "Month 13")
A11: CPA-Gebühr pro Vermittlung (€) | B11: 150 | C11: Platzhalter — typische CFD/FX-Broker-CPA liegt bei €100–300. Mit dem tatsächlichen Partner verhandeln.
A12: Konversionsrate Neuabo → Broker-Signup | B12: 0.2 | C12: Anteil der monatlichen Netto-Neuabos, die sich zusätzlich beim Partnerbroker registrieren
A13: Startmonat (1–36) | B13: 13 | C13: Monat 13 = Jahr-2-Monat-1, entspricht dem 'Month-13-Breakeven'-Trigger
A15: 3. WARENEINSATZ (Hosting, Infrastruktur, Plattformgebühren)
A16: Whop-Plattformgebühr (% vom Runnr-Umsatz) | B16: 0.1 | C16: Platzhalter — mit aktuellem Whop-Gebührenmodell abgleichen
A17: Fixe Infrastrukturkosten (€/Monat) | B17: 150 | C17: Railway-Hosting, Marktdaten-Feeds, Alpaca etc.
A19: 4. PERSONALKOSTEN — Geschäftsführergehalt als linearer Ramp
A20: Geschäftsführergehalt ab Monat 7 (Start, €/Monat) | B20: 1000 | C20: Nach ALG-I-Ende (Annahmen!B58). Laut Selbstauskunft: Haushalt hat Deckungslücke von €785/Monat ohne ALG I — €1.000 = Mindestbedarf + kleiner Puffer.
A21: Geschäftsführergehalt Monat 36 (€/Monat) | B21: 5000 | C21: Zielwert Ende Jahr 3, unverändert
A22: Freelancer-Honorar Jahr 2 (€/Monat) | B22: 800 | C22: z.B. Teilzeit-Support/Dev — optional, auf 0 setzen falls nicht geplant
A23: Freelancer-Honorar Jahr 3 (€/Monat) | B23: 1000
A24: Freelancer Startmonat (1–36) | B24: 500 | C24: Monat 19 = Jahr-2-Monat-7
B25: 2500
A26: 5. SONSTIGE BETRIEBSKOSTEN — Werbung als linearer Ramp
A27: Miete / Homeoffice-Pauschale (€/Monat) | B27: 150
A28: Werbung Monat 1 (€/Monat) | B28: 600 | C28: Startwert — entspricht der ursprünglichen Marketing-Zeile aus dem 12-Monats-Budget
A29: Werbung Monat 36 (€/Monat) | B29: 3000 | C29: Zielwert am Ende Jahr 3 — lineare Interpolation Monat 1→36 in Monatsdetail. Influencer-Budget noch unsicher.
A30: Buchführung / Steuerberater (€/Monat) | B30: 200
A32: 6. INVESTITION & ABSCHREIBUNG (AfA)
A33: Investitionsvolumen (€) | B33: 40000 | C33: entspricht dem Investitionsanteil aus dem KfW-Antrag (Software/IP, Infrastruktur, Equipment)
A34: Nutzungsdauer (Jahre) | B34: 3 | C34: AfA-Tabelle: Software/IT-Equipment i.d.R. 3 Jahre — mit Steuerberater final abstimmen
A35: → Jährliche AfA (€) | B35: =B33/B34
A36: → Monatliche AfA (€) | B36: =B35/12
A38: 7. KFW-STARTGELD-DARLEHEN (067) | B38: 120000
A39: Auszahlungsbetrag (€) | B39: 120000
A40: Restsaldo nach ProFIT-Sondertilgung (€) | B40: 0
A41: Monat der ProFIT-Sondertilgung (1–36) | B41: 6 | C41: Dezember 2026 = Monat 6
A42: Effektiver Jahreszins | B42: 0.0393 | C42: Hergeleitet aus den Zinsbeträgen des 12-Monats-Budgets (€556,75/Monat auf €170.000)
A43: → Monatlicher Zinssatz | B43: =B42/12
A44: Tilgungsfreie Anlaufjahre | B44: 2 | C44: KfW StartGeld: bis 2 Jahre tilgungsfrei bei 10 Jahren Laufzeit — mit Deutsche Bank final klären
A45: Gesamtlaufzeit (Jahre) | B45: 10
A46: → Tilgungsmonate | B46: =(B45-B44)*12
...

Sheet Rentabilitaet
A1: RENTABILITÄTSVORSCHAU — 3 Geschäftsjahre
A2: Jahr 1 = Jul-26–Jun-27 (KfW-Laufzeit) | Jahr 2 = Jul-27–Jun-28 | Jahr 3 = Jul-28–Jun-29
B4: Jahr 1 (Jul-26–Jun-27) | C4: Jahr 2 (Jul-27–Jun-28) | D4: Jahr 3 (Jul-28–Jun-29)
A6: Nettoumsatz
A7: Runnr SaaS-Abos | B7: =SUM(Monatsdetail!C10:N10) | C7: =SUM(Monatsdetail!O10:Z10) | D7: =SUM(Monatsdetail!AA10:AL10)
A8: Broker-Vermittlung (CPA) | B8: =SUM(Monatsdetail!C12:N12) | C8: =SUM(Monatsdetail!O12:Z12) | D8: =SUM(Monatsdetail!AA12:AL12)
A9: Glacifraga Institutional | B9: =SUM(Monatsdetail!C13:N13) | C9: =SUM(Monatsdetail!O13:Z13) | D9: =SUM(Monatsdetail!AA13:AL13)
A10: GESAMTUMSATZ | B10: =SUM(B7:B9) | C10: =SUM(C7:C9) | D10: =SUM(D7:D9)
A11: davon: Umsatz-Exit-Run-Rate (letzter Monat × 12) | B11: =Monatsdetail!N14*12 | C11: =Monatsdetail!Z14*12 | D11: =Monatsdetail!AL14*12
A13: Wareneinsatz | B13: =SUM(Monatsdetail!C15:N15) | C13: =SUM(Monatsdetail!O15:Z15) | D13: =SUM(Monatsdetail!AA15:AL15)
A14: ROHERTRAG | B14: =B10-B13 | C14: =C10-C13 | D14: =D10-D13
A16: Personal (Geschäftsführergehalt + Freelancer) | B16: =SUM(Monatsdetail!C17:N17) | C16: =SUM(Monatsdetail!O17:Z17) | D16: =SUM(Monatsdetail!AA17:AL17)
A17: Miete / Homeoffice | B17: =SUM(Monatsdetail!C18:N18) | C17: =SUM(Monatsdetail!O18:Z18) | D17: =SUM(Monatsdetail!AA18:AL18)
A18: Werbung | B18: =SUM(Monatsdetail!C19:N19) | C18: =SUM(Monatsdetail!O19:Z19) | D18: =SUM(Monatsdetail!AA19:AL19)
A19: Buchführung / Steuerberater | B19: =SUM(Monatsdetail!C20:N20) | C19: =SUM(Monatsdetail!O20:Z20) | D19: =SUM(Monatsdetail!AA20:AL20)
A20: Abschreibungen | B20: =SUM(Monatsdetail!C21:N21) | C20: =SUM(Monatsdetail!O21:Z21) | D20: =SUM(Monatsdetail!AA21:AL21)
A21: BETRIEBSERGEBNIS (EBIT) | B21: =B14-B16-B17-B18-B19-B20 | C21: =C14-C16-C17-C18-C19-C20 | D21: =D14-D16-D17-D18-D19-D20
A23: Zinsen (KfW-Darlehen) | B23: =SUM(Monatsdetail!C26:N26) | C23: =SUM(Monatsdetail!O26:Z26) | D23: =SUM(Monatsdetail!AA26:AL26)
A24: EBT (vor Steuern) | B24: =B21-B23 | C24: =C21-C23 | D24: =D21-D23
A26: Verlustvortrag (Beginn Geschäftsjahr) | B26: 0 | C26: =B29 | D26: =C29
A27: Zu versteuerndes Ergebnis | B27: =MAX(0,B24-B26) | C27: =MAX(0,C24-C26) | D27: =MAX(0,D24-D26)
A28: Steuern (Satz: Annahmen!B50) | B28: =B27*Annahmen!$B$50 | C28: =C27*Annahmen!$B$50 | D28: =D27*Annahmen!$B$50
A29: Verlustvortrag (Ende Geschäftsjahr) | B29: =MAX(0,B26-MAX(0,B24))+MAX(0,-B24) | C29: =MAX(0,C26-MAX(0,C24))+MAX(0,-C24) | D29: =MAX(0,D26-MAX(0,D24))+MAX(0,-D24)
A30: JAHRESÜBERSCHUSS | B30: =B24-B28 | C30: =C24-C28 | D30: =D24-D28
A32: + Abschreibungen (nicht zahlungswirksam) | B32: =B20 | C32: =C20 | D32: =D20
A33: - Reguläre Tilgung (Kredit) | B33: =SUM(Monatsdetail!C27:N27) | C33: =SUM(Monatsdetail!O27:Z27) | D33: =SUM(Monatsdetail!AA27:AL27)
A34: VERFÜGBARES EINKOMMEN (Cashflow) | B34: =B30+B32-B33 | C34: =C30+C32-C33 | D34: =D30+D32-D33
A36: Kreditsaldo Jahresende (€) | B36: =Monatsdetail!N28 | C36: =Monatsdetail!Z28 | D36: =Monatsdetail!AL28

Sheet Monatsdetail
A1: MONATSDETAIL — 36-Monats-Engine (Jul-26 bis Jun-29)
A2: Grüne Zeilen = Eingaben (editierbar) | Schwarze Zeilen = Formeln, automatisch berechnet
A4: Monat # | C4: 1 | D4: 2 | E4: 3 | F4: 4 | G4: 5 | H4: 6 | I4: 7 | J4: 8 | K4: 9 | L4: 10 | M4: 11 | N4: 12 | O4: 13 | P4: 14 | Q4: 15 | R4: 16 | S4: 17 | T4: 18 | U4: 19 | V4: 20 | W4: 21 | X4: 22 | Y4: 23 | Z4: 24 | AA4: 25 | AB4: 26 | AC4: 27 | AD4: 28 | AE4: 29 | AF4: 30 | AG4: 31 | AH4: 32 | AI4: 33 | AJ4: 34 | AK4: 35 | AL4: 36
A5: Periode | C5: Jul-26 | D5: Aug-26 | E5: Sep-26 | F5: Okt-26 | G5: Nov-26 | H5: Dez-26 | I5: Jan-27 | J5: Feb-27 | K5: Mär-27 | L5: Apr-27 | M5: Mai-27 | N5: Jun-27 | O5: Jul-27 | P5: Aug-27 | Q5: Sep-27 | R5: Okt-27 | S5: Nov-27 | T5: Dez-27 | U5: Jan-28 | V5: Feb-28 | W5: Mär-28 | X5: Apr-28 | Y5: Mai-28 | Z5: Jun-28 | AA5: Jul-28 | AB5: Aug-28 | AC5: Sep-28 | AD5: Okt-28 | AE5: Nov-28 | AF5: Dez-28 | AG5: Jan-29 | AH5: Feb-29 | AI5: Mär-29 | AJ5: Apr-29 | AK5: Mai-29 | AL5: Jun-29
A6: Geschäftsjahr | C6: Jahr 1 | D6: Jahr 1 | E6: Jahr 1 | F6: Jahr 1 | G6: Jahr 1 | H6: Jahr 1 | I6: Jahr 1 | J6: Jahr 1 | K6: Jahr 1 | L6: Jahr 1 | M6: Jahr 1 | N6: Jahr 1 | O6: Jahr 2 | P6: Jahr 2 | Q6: Jahr 2 | R6: Jahr 2 | S6: Jahr 2 | T6: Jahr 2 | U6: Jahr 2 | V6: Jahr 2 | W6: Jahr 2 | X6: Jahr 2 | Y6: Jahr 2 | Z6: Jahr 2 | AA6: Jahr 3 | AB6: Jahr 3 | AC6: Jahr 3 | AD6: Jahr 3 | AE6: Jahr 3 | AF6: Jahr 3 | AG6: Jahr 3 | AH6: Jahr 3 | AI6: Jahr 3 | AJ6: Jahr 3 | AK6: Jahr 3 | AL6: Jahr 3
A8: Netto-Neuzugänge zahlende Abos (Stk.) | C8: 10 | D8: 15 | E8: 20 | F8: 30 | G8: 40 | H8: 50 | I8: 60 | J8: 65 | K8: 65 | L8: 60 | M8: 50 | N8: 35 | O8: 45 | P8: 45 | Q8: 45 | R8: 45 | S8: 42 | T8: 42 | U8: 42 | V8: 42 | W8: 40 | X8: 40 | Y8: 40 | Z8: 40 | AA8: 70 | AB8: 70 | AC8: 72 | AD8: 72 | AE8: 75 | AF8: 75 | AG8: 78 | AH8: 78 | AI8: 80 | AJ8: 80 | AK8: 82 | AL8: 82
A9: Kumulierte zahlende Abos (Stk.) | C9: =C8 | D9: =C9+D8 | E9: =D9+E8 | F9: =E9+F8 | G9: =F9+G8 | H9: =G9+H8 | I9: =H9+I8 | J9: =I9+J8 | K9: =J9+K8 | ... AL9: =AK9+AL8
A10: Runnr SaaS-Umsatz (€) | C10: =C9*Annahmen!$B$8 | D10: =D9*Annahmen!$B$8 | E10: =E9*Annahmen!$B$8 | F10: =F9*Annahmen!$B$8 | G10: =G9*Annahmen!$B$8 | H10: =H9*Annahmen!$B$8 | I10: =I9*Annahmen!$B$8 | J10: =J9*Annahmen!$B$8 | ... AL10: =AL9*Annahmen!$B$8
A11: Broker-Vermittlungen (Stk.) | C11: =IF(C4>=Annahmen!$B$13,C8*Annahmen!$B$12,0) | D11: =IF(D4>=Annahmen!$B$13,D8*Annahmen!$B$12,0) | E11: =IF(E4>=Annahmen!$B$13,E8*Annahmen!$B$12,0) | F11: =IF(F4>=Annahmen!$B$13,F8*Annahmen!$B$12,0) | G11: =IF(G4>=Annahmen!$B$13,G8*Annahmen!$B$12,0) | H11: =IF(H4>=Annahmen!$B$13,H8*Annahmen!$B$12,0) | I11: =IF(I4>=Annahmen!$B$13,I8*Annahmen!$B$12,0) | J11: =IF(J4>=Annahmen!$B$13,J8*Annahmen!$B$12,0) | ... AL11: =IF(AL4>=Annahmen!$B$13,AL8*Annahmen!$B$12,0)
A12: Broker-Umsatz (€) | C12: =C11*Annahmen!$B$11 | D12: =D11*Annahmen!$B$11 | E12: =E11*Annahmen!$B$11 | F12: =F11*Annahmen!$B$11 | G12: =G11*Annahmen!$B$11 | H12: =H11*Annahmen!$B$11 | I12: =I11*Annahmen!$B$11 | J12: =J11*Annahmen!$B$11 | ... AL12: =AL11*Annahmen!$B$11
A13: Glacifraga-Umsatz (€) | C13: 0 | D13: 0 | E13: 0 | F13: 0 | G13: 0 | H13: 0 | I13: 0 | J13: 0 | K13: 0 | L13: 0 | M13: 0 | N13: 0 | O13: 0 | P13: 0 | Q13: 0 | R13: 2000 | S13: 2000 | T13: 2000 | U13: 2000 | V13: 2000 | W13: 2000 | X13: 2000 | Y13: 2000 | Z13: 2000 | AA13: 2500 | AB13: 2500 | AC13: 2500 | AD13: 4500 | AE13: 4500 | AF13: 4500 | AG13: 4500 | AH13: 4500 | AI13: 4500 | AJ13: 4500 | AK13: 4500 | AL13: 4500
A14: GESAMTUMSATZ (€) | C14: =C10+C12+C13 | D14: =D10+D12+D13 | E14: =E10+E12+E13 | F14: =F10+F12+F13 | G14: =G10+G12+G13 | H14: =H10+H12+H13 | I14: =I10+I12+I13 | J14: =J10+J12+J13 | ... AL14: =AL10+AL12+AL13
A15: Wareneinsatz (€) | C15: =C10*Annahmen!$B$16+Annahmen!$B$17 | D15: =D10*Annahmen!$B$16+Annahmen!$B$17 | E15: =E10*Annahmen!$B$16+Annahmen!$B$17 | F15: =F10*Annahmen!$B$16+Annahmen!$B$17 | G15: =G10*Annahmen!$B$16+Annahmen!$B$17 | H15: =H10*Annahmen!$B$16+Annahmen!$B$17 | I15: =I10*Annahmen!$B$16+Annahmen!$B$17 | J15: =J10*Annahmen!$B$16+Annahmen!$B$17 | ... AL15: =AL10*Annahmen!$B$16+Annahmen!$B$17
A16: Rohertrag (€) | C16: =C14-C15 | D16: =D14-D15 | E16: =E14-E15 | F16: =F14-F15 | G16: =G14-G15 | H16: =H14-H15 | I16: =I14-I15 | J16: =J14-J15 | ... AL16: =AL14-AL15
A17: Personal (€) | C17: =IF(C4<=Annahmen!$B$58,0,Annahmen!$B$20+(Annahmen!$B$21-Annahmen!$B$20)*(C4-Annahmen!$B$58-1)/(35-Annahmen!$B$58))+IF(C4<Annahmen!$B$24,0,IF(C4<=24,Annahmen!$B$22,Annahmen!$B$23)) | D17: =IF(D4<=Annahmen!$B$58,0,Annahmen!$B$20+(Annahmen!$B$21-Annahmen!$B$20)*(D4-Annahmen!$B$58-1)/(35-Annahmen!$B$58))+IF(D4<Annahmen!$B$24,0,IF(D4<=24,Annahmen!$B$22,Annahmen!$B$23)) | E17: =IF(E4<=Annahmen!$B$58,0,Annahmen!$B$20+(Annahmen!$B$21-Annahmen!$B$20)*(E4-Annahmen!$B$58-1)/(35-Annahmen!$B$58))+IF(E4<Annahmen!$B$24,0,IF(E4<=24,Annahmen!$B$22,Annahmen!$B$23)) | F17: =IF(F4<=Annahmen!$B$58,0,Annahmen!$B$20+(Annahmen!$B$21-Annahmen!$B$20)*(F4-Annahmen!$B$58-1)/(35-Annahmen!$B$58))+IF(F4<Annahmen!$B$24,0,IF(F4<=24,Annahmen!$B$22,Annahmen!$B$23)) | G17: =IF(G4<=Annahmen!$B$58,0,Annahmen!$B$20+(Annahmen!$B$21-Annahmen!$B$20)*(G4-Annahmen!$B$58-1)/(35-Annahmen!$B$58))+IF(G4<Annahmen!$B$24,0,IF(G4<=24,Annahmen!$B$22,Annahmen!$B$23)) | H17: =IF(H4<=Annahmen!$B$58,0,Annahmen!$B$20+(Annahmen!$B$21-Annahmen!$B$20)*(H4-Annahmen!$B$58-1)/(35-Annahmen!$B$58))+IF(H4<Annahmen!$B$24,0,IF(H4<=24,Annahmen!$B$22,Annahmen!$B$23)) | I17: =IF(I4<=Annahmen!$B$58,0,Annahmen!$B$20+(Annahmen!$B$21-Annahmen!$B$20)*(I4-Annahmen!$B$58-1)/(35-Annahmen!$B$58))+IF(I4<Annahmen!$B$24,0,IF(I4<=24,Annahmen!$B$22,Annahmen!$B$23)) | J17: =IF(J4<=Annahmen!$B$58,0,Annahmen!$B$20+(Annahmen!$B$21-Annahmen!$B$20)*(J4-Annahmen!$B$58-1)/(35-Annahmen!$B$58))+IF(J4<Annahmen!$B$24,0,IF(J4<=24,Annahmen!$B$22,Annahmen!$B$23)) | ... AL17: =IF(AL4<=Annahmen!$B$58,0,Annahmen!$B$20+(Annahmen!$B$21-Annahmen!$B$20)*(AL4-Annahmen!$B$58-1)/(35-Annahmen!$B$58))+IF(AL4<Annahmen!$B$24,0,IF(AL4<=24,Annahmen!$B$22,Annahmen!$B$23))
A18: Miete/Homeoffice (€) | C18: =Annahmen!$B$27 | D18: =Annahmen!$B$27 | E18: =Annahmen!$B$27 | F18: =Annahmen!$B$27 | G18: =Annahmen!$B$27 | H18: =Annahmen!$B$27 | I18: =Annahmen!$B$27 | J18: =Annahmen!$B$27 | ... AL18: =Annahmen!$B$27
A19: Werbung (€) | C19: =Annahmen!$B$28+(Annahmen!$B$29-Annahmen!$B$28)*(C4-1)/35 | D19: =Annahmen!$B$28+(Annahmen!$B$29-Annahmen!$B$28)*(D4-1)/35 | E19: =Annahmen!$B$28+(Annahmen!$B$29-Annahmen!$B$28)*(E4-1)/35 | F19: =Annahmen!$B$28+(Annahmen!$B$29-Annahmen!$B$28)*(F4-1)/35 | G19: =Annahmen!$B$28+(Annahmen!$B$29-Annahmen!$B$28)*(G4-1)/35 | H19: =Annahmen!$B$28+(Annahmen!$B$29-Annahmen!$B$28)*(H4-1)/35 | I19: =Annahmen!$B$28+(Annahmen!$B$29-Annahmen!$B$28)*(I4-1)/35 | J19: =Annahmen!$B$28+(Annahmen!$B$29-Annahmen!$B$28)*(J4-1)/35 | ... AL19: =Annahmen!$B$28+(Annahmen!$B$29-Annahmen!$B$28)*(AL4-1)/35
A20: Buchführung (€) | C20: =Annahmen!$B$30 | D20: =Annahmen!$B$30 | E20: =Annahmen!$B$30 | F20: =Annahmen!$B$30 | G20: =Annahmen!$B$30 | H20: =Annahmen!$B$30 | I20: =Annahmen!$B$30 | J20: =Annahmen!$B$30 | ... AL20: =Annahmen!$B$30
A21: Abschreibung (€) | C21: =Annahmen!$B$36 | D21: =Annahmen!$B$36 | E21: =Annahmen!$B$36 | F21: =Annahmen!$B$36 | G21: =Annahmen!$B$36 | H21: =Annahmen!$B$36 | I21: =Annahmen!$B$36 | J21: =Annahmen!$B$36 | ... AL21: =Annahmen!$B$36
A22: BETRIEBSERGEBNIS / EBIT (€) | C22: =C16-C17-C18-C19-C20-C21 | D22: =D16-D17-D18-D19-D20-D21 | E22: =E16-E17-E18-E19-E20-E21 | F22: =F16-F17-F18-F19-F20-F21 | G22: =G16-G17-G18-G19-G20-G21 | H22: =H16-H17-H18-H19-H20-H21 | I22: =I16-I17-I18-I19-I20-I21 | J22: =J16-J17-J18-J19-J20-J21 | ... AL22: =AL16-AL17-AL18-AL19-AL20-AL21
A24: Kreditsaldo Beginn (€) | C24: =Annahmen!$B$39 | D24: =C28 | E24: =D28 | F24: =E28 | G24: =F28 | H24: =G28 | I24: =H28 | J24: =I28 | K24: =J28 | ... AL24: =AK28
A25: ProFIT-Sondertilgung (€) | C25: =IF(C4=Annahmen!$B$41,Annahmen!$B$39-Annahmen!$B$40,0) | D25: =IF(D4=Annahmen!$B$41,Annahmen!$B$39-Annahmen!$B$40,0) | E25: =IF(E4=Annahmen!$B$41,Annahmen!$B$39-Annahmen!$B$40,0) | F25: =IF(F4=Annahmen!$B$41,Annahmen!$B$39-Annahmen!$B$40,0) | G25: =IF(G4=Annahmen!$B$41,Annahmen!$B$39-Annahmen!$B$40,0) | H25: =IF(H4=Annahmen!$B$41,Annahmen!$B$39-Annahmen!$B$40,0) | I25: =IF(I4=Annahmen!$B$41,Annahmen!$B$39-Annahmen!$B$40,0) | J25: =IF(J4=Annahmen!$B$41,Annahmen!$B$39-Annahmen!$B$40,0) | ... AL25: =IF(AL4=Annahmen!$B$41,Annahmen!$B$39-Annahmen!$B$40,0)
A26: Zinsen (€) | C26: =(C24-C25)*Annahmen!$B$43 | D26: =(D24-D25)*Annahmen!$B$43 | E26: =(E24-E25)*Annahmen!$B$43 | F26: =(F24-F25)*Annahmen!$B$43 | G26: =(G24-G25)*Annahmen!$B$43 | H26: =(H24-H25)*Annahmen!$B$43 | I26: =(I24-I25)*Annahmen!$B$43 | J26: =(J24-J25)*Annahmen!$B$43 | ... AL26: =(AL24-AL25)*Annahmen!$B$43
A27: Reguläre Tilgung (€) | C27: =IF(C4>Annahmen!$B$44*12,Annahmen!$B$47,0) | D27: =IF(D4>Annahmen!$B$44*12,Annahmen!$B$47,0) | E27: =IF(E4>Annahmen!$B$44*12,Annahmen!$B$47,0) | F27: =IF(F4>Annahmen!$B$44*12,Annahmen!$B$47,0) | G27: =IF(G4>Annahmen!$B$44*12,Annahmen!$B$47,0) | H27: =IF(H4>Annahmen!$B$44*12,Annahmen!$B$47,0) | I27: =IF(I4>Annahmen!$B$44*12,Annahmen!$B$47,0) | J27: =IF(J4>Annahmen!$B$44*12,Annahmen!$B$47,0) | ... AL27: =IF(AL4>Annahmen!$B$44*12,Annahmen!$B$47,0)
A28: Kreditsaldo Ende (€) | C28: =C24-C25-C27 | D28: =D24-D25-D27 | E28: =E24-E25-E27 | F28: =F24-F25-F27 | G28: =G24-G25-G27 | H28: =H24-H25-H27 | I28: =I24-I25-I27 | J28: =J24-J25-J27 | ... AL28: =AL24-AL25-AL27
A30: EBT vor Steuern (€) | C30: =C22-C26 | D30: =D22-D26 | E30: =E22-E26 | F30: =F22-F26 | G30: =G22-G26 | H30: =H22-H26 | I30: =I22-I26 | J30: =J22-J26 | ... AL30: =AL22-AL26
